[2025-02-04T20:19:47.161+0000] {local_task_job_runner.py:123} INFO - ::group::Pre task execution logs
[2025-02-04T20:19:47.175+0000] {taskinstance.py:2613} INFO - Dependencies all met for dep_context=non-requeueable deps ti=<TaskInstance: northwind_meltano.test_meltano_postgres manual__2025-02-04T20:19:46.799325+00:00 [queued]>
[2025-02-04T20:19:47.182+0000] {taskinstance.py:2613} INFO - Dependencies all met for dep_context=requeueable deps ti=<TaskInstance: northwind_meltano.test_meltano_postgres manual__2025-02-04T20:19:46.799325+00:00 [queued]>
[2025-02-04T20:19:47.183+0000] {taskinstance.py:2866} INFO - Starting attempt 1 of 1
[2025-02-04T20:19:47.254+0000] {taskinstance.py:2889} INFO - Executing <Task(DockerOperator): test_meltano_postgres> on 2025-02-04 20:19:46.799325+00:00
[2025-02-04T20:19:47.262+0000] {standard_task_runner.py:104} INFO - Running: ['***', 'tasks', 'run', 'northwind_meltano', 'test_meltano_postgres', 'manual__2025-02-04T20:19:46.799325+00:00', '--job-id', '11', '--raw', '--subdir', 'DAGS_FOLDER/northwind_etl/northwind_meltano.py', '--cfg-path', '/tmp/tmp4032xbox']
[2025-02-04T20:19:47.264+0000] {standard_task_runner.py:105} INFO - Job 11: Subtask test_meltano_postgres
[2025-02-04T20:19:47.266+0000] {logging_mixin.py:190} WARNING - /home/***/.local/lib/python3.12/site-packages/***/task/task_runner/standard_task_runner.py:70 DeprecationWarning: This process (pid=570) is multi-threaded, use of fork() may lead to deadlocks in the child.
[2025-02-04T20:19:47.266+0000] {standard_task_runner.py:72} INFO - Started process 571 to run task
[2025-02-04T20:19:47.302+0000] {task_command.py:467} INFO - Running <TaskInstance: northwind_meltano.test_meltano_postgres manual__2025-02-04T20:19:46.799325+00:00 [running]> on host bc28df93379b
[2025-02-04T20:19:47.375+0000] {taskinstance.py:3132} INFO - Exporting env vars: AIRFLOW_CTX_DAG_OWNER='gabriel' AIRFLOW_CTX_DAG_ID='northwind_meltano' AIRFLOW_CTX_TASK_ID='test_meltano_postgres' AIRFLOW_CTX_EXECUTION_DATE='2025-02-04T20:19:46.799325+00:00' AIRFLOW_CTX_TRY_NUMBER='1' AIRFLOW_CTX_DAG_RUN_ID='manual__2025-02-04T20:19:46.799325+00:00'
[2025-02-04T20:19:47.376+0000] {taskinstance.py:731} INFO - ::endgroup::
[2025-02-04T20:19:47.439+0000] {docker.py:379} INFO - Starting docker container from image meu-meltano
[2025-02-04T20:19:48.181+0000] {taskinstance.py:3311} ERROR - Task failed with exception
Traceback (most recent call last):
  File "/home/airflow/.local/lib/python3.12/site-packages/docker/api/client.py", line 275, in _raise_for_status
    response.raise_for_status()
  File "/home/airflow/.local/lib/python3.12/site-packages/requests/models.py", line 1024, in raise_for_status
    raise HTTPError(http_error_msg, response=self)
requests.exceptions.HTTPError: 404 Client Error: Not Found for url: http://docker-socket-proxy:2375/v1.45/containers/b54644c4c7220f5bd00693bde622cd43b3e089b566b54a0603a9c23a5df2caa0/start

The above exception was the direct cause of the following exception:

Traceback (most recent call last):
  File "/home/airflow/.local/lib/python3.12/site-packages/airflow/models/taskinstance.py", line 767, in _execute_task
    result = _execute_callable(context=context, **execute_callable_kwargs)
             ^^^^^^^^^^^^^^^^^^^^^^^^^^^^^^^^^^^^^^^^^^^^^^^^^^^^^^^^^^^^^
  File "/home/airflow/.local/lib/python3.12/site-packages/airflow/models/taskinstance.py", line 733, in _execute_callable
    return ExecutionCallableRunner(
           ^^^^^^^^^^^^^^^^^^^^^^^^
  File "/home/airflow/.local/lib/python3.12/site-packages/airflow/utils/operator_helpers.py", line 252, in run
    return self.func(*args, **kwargs)
           ^^^^^^^^^^^^^^^^^^^^^^^^^^
  File "/home/airflow/.local/lib/python3.12/site-packages/airflow/models/baseoperator.py", line 422, in wrapper
    return func(self, *args, **kwargs)
           ^^^^^^^^^^^^^^^^^^^^^^^^^^^
  File "/home/airflow/.local/lib/python3.12/site-packages/airflow/providers/docker/operators/docker.py", line 519, in execute
    return self._run_image()
           ^^^^^^^^^^^^^^^^^
  File "/home/airflow/.local/lib/python3.12/site-packages/airflow/providers/docker/operators/docker.py", line 396, in _run_image
    return self._run_image_with_mounts(self.mounts, add_tmp_variable=False)
           ^^^^^^^^^^^^^^^^^^^^^^^^^^^^^^^^^^^^^^^^^^^^^^^^^^^^^^^^^^^^^^^^
  File "/home/airflow/.local/lib/python3.12/site-packages/airflow/providers/docker/operators/docker.py", line 443, in _run_image_with_mounts
    self.cli.start(self.container["Id"])
  File "/home/airflow/.local/lib/python3.12/site-packages/docker/utils/decorators.py", line 19, in wrapped
    return f(self, resource_id, *args, **kwargs)
           ^^^^^^^^^^^^^^^^^^^^^^^^^^^^^^^^^^^^^
  File "/home/airflow/.local/lib/python3.12/site-packages/docker/api/container.py", line 1136, in start
    self._raise_for_status(res)
  File "/home/airflow/.local/lib/python3.12/site-packages/docker/api/client.py", line 277, in _raise_for_status
    raise create_api_error_from_http_exception(e) from e
          ^^^^^^^^^^^^^^^^^^^^^^^^^^^^^^^^^^^^^^^
  File "/home/airflow/.local/lib/python3.12/site-packages/docker/errors.py", line 39, in create_api_error_from_http_exception
    raise cls(e, response=response, explanation=explanation) from e
docker.errors.NotFound: 404 Client Error for http://docker-socket-proxy:2375/v1.45/containers/b54644c4c7220f5bd00693bde622cd43b3e089b566b54a0603a9c23a5df2caa0/start: Not Found ("network meltano_network not found")
[2025-02-04T20:19:48.202+0000] {taskinstance.py:1225} INFO - Marking task as FAILED. dag_id=northwind_meltano, task_id=test_meltano_postgres, run_id=manual__2025-02-04T20:19:46.799325+00:00, execution_date=20250204T201946, start_date=20250204T201947, end_date=20250204T201948
[2025-02-04T20:19:48.214+0000] {taskinstance.py:340} INFO - ::group::Post task execution logs
[2025-02-04T20:19:48.215+0000] {standard_task_runner.py:124} ERROR - Failed to execute job 11 for task test_meltano_postgres (404 Client Error for http://docker-socket-proxy:2375/v1.45/containers/b54644c4c7220f5bd00693bde622cd43b3e089b566b54a0603a9c23a5df2caa0/start: Not Found ("network meltano_network not found"); 571)
Traceback (most recent call last):
  File "/home/airflow/.local/lib/python3.12/site-packages/docker/api/client.py", line 275, in _raise_for_status
    response.raise_for_status()
  File "/home/airflow/.local/lib/python3.12/site-packages/requests/models.py", line 1024, in raise_for_status
    raise HTTPError(http_error_msg, response=self)
requests.exceptions.HTTPError: 404 Client Error: Not Found for url: http://docker-socket-proxy:2375/v1.45/containers/b54644c4c7220f5bd00693bde622cd43b3e089b566b54a0603a9c23a5df2caa0/start

The above exception was the direct cause of the following exception:

Traceback (most recent call last):
  File "/home/airflow/.local/lib/python3.12/site-packages/airflow/task/task_runner/standard_task_runner.py", line 117, in _start_by_fork
    ret = args.func(args, dag=self.dag)
          ^^^^^^^^^^^^^^^^^^^^^^^^^^^^^
  File "/home/airflow/.local/lib/python3.12/site-packages/airflow/cli/cli_config.py", line 49, in command
    return func(*args, **kwargs)
           ^^^^^^^^^^^^^^^^^^^^^
  File "/home/airflow/.local/lib/python3.12/site-packages/airflow/utils/cli.py", line 116, in wrapper
    return f(*args, **kwargs)
           ^^^^^^^^^^^^^^^^^^
  File "/home/airflow/.local/lib/python3.12/site-packages/airflow/cli/commands/task_command.py", line 483, in task_run
    task_return_code = _run_task_by_selected_method(args, _dag, ti)
                       ^^^^^^^^^^^^^^^^^^^^^^^^^^^^^^^^^^^^^^^^^^^^
  File "/home/airflow/.local/lib/python3.12/site-packages/airflow/cli/commands/task_command.py", line 256, in _run_task_by_selected_method
    return _run_raw_task(args, ti)
           ^^^^^^^^^^^^^^^^^^^^^^^
  File "/home/airflow/.local/lib/python3.12/site-packages/airflow/cli/commands/task_command.py", line 341, in _run_raw_task
    return ti._run_raw_task(
           ^^^^^^^^^^^^^^^^^
  File "/home/airflow/.local/lib/python3.12/site-packages/airflow/utils/session.py", line 97, in wrapper
    return func(*args, session=session, **kwargs)
           ^^^^^^^^^^^^^^^^^^^^^^^^^^^^^^^^^^^^^^
  File "/home/airflow/.local/lib/python3.12/site-packages/airflow/models/taskinstance.py", line 3005, in _run_raw_task
    return _run_raw_task(
           ^^^^^^^^^^^^^^
  File "/home/airflow/.local/lib/python3.12/site-packages/airflow/models/taskinstance.py", line 273, in _run_raw_task
    TaskInstance._execute_task_with_callbacks(
  File "/home/airflow/.local/lib/python3.12/site-packages/airflow/models/taskinstance.py", line 3159, in _execute_task_with_callbacks
    result = self._execute_task(context, task_orig)
             ^^^^^^^^^^^^^^^^^^^^^^^^^^^^^^^^^^^^^^
  File "/home/airflow/.local/lib/python3.12/site-packages/airflow/models/taskinstance.py", line 3183, in _execute_task
    return _execute_task(self, context, task_orig)
           ^^^^^^^^^^^^^^^^^^^^^^^^^^^^^^^^^^^^^^^
  File "/home/airflow/.local/lib/python3.12/site-packages/airflow/models/taskinstance.py", line 767, in _execute_task
    result = _execute_callable(context=context, **execute_callable_kwargs)
             ^^^^^^^^^^^^^^^^^^^^^^^^^^^^^^^^^^^^^^^^^^^^^^^^^^^^^^^^^^^^^
  File "/home/airflow/.local/lib/python3.12/site-packages/airflow/models/taskinstance.py", line 733, in _execute_callable
    return ExecutionCallableRunner(
           ^^^^^^^^^^^^^^^^^^^^^^^^
  File "/home/airflow/.local/lib/python3.12/site-packages/airflow/utils/operator_helpers.py", line 252, in run
    return self.func(*args, **kwargs)
           ^^^^^^^^^^^^^^^^^^^^^^^^^^
  File "/home/airflow/.local/lib/python3.12/site-packages/airflow/models/baseoperator.py", line 422, in wrapper
    return func(self, *args, **kwargs)
           ^^^^^^^^^^^^^^^^^^^^^^^^^^^
  File "/home/airflow/.local/lib/python3.12/site-packages/airflow/providers/docker/operators/docker.py", line 519, in execute
    return self._run_image()
           ^^^^^^^^^^^^^^^^^
  File "/home/airflow/.local/lib/python3.12/site-packages/airflow/providers/docker/operators/docker.py", line 396, in _run_image
    return self._run_image_with_mounts(self.mounts, add_tmp_variable=False)
           ^^^^^^^^^^^^^^^^^^^^^^^^^^^^^^^^^^^^^^^^^^^^^^^^^^^^^^^^^^^^^^^^
  File "/home/airflow/.local/lib/python3.12/site-packages/airflow/providers/docker/operators/docker.py", line 443, in _run_image_with_mounts
    self.cli.start(self.container["Id"])
  File "/home/airflow/.local/lib/python3.12/site-packages/docker/utils/decorators.py", line 19, in wrapped
    return f(self, resource_id, *args, **kwargs)
           ^^^^^^^^^^^^^^^^^^^^^^^^^^^^^^^^^^^^^
  File "/home/airflow/.local/lib/python3.12/site-packages/docker/api/container.py", line 1136, in start
    self._raise_for_status(res)
  File "/home/airflow/.local/lib/python3.12/site-packages/docker/api/client.py", line 277, in _raise_for_status
    raise create_api_error_from_http_exception(e) from e
          ^^^^^^^^^^^^^^^^^^^^^^^^^^^^^^^^^^^^^^^
  File "/home/airflow/.local/lib/python3.12/site-packages/docker/errors.py", line 39, in create_api_error_from_http_exception
    raise cls(e, response=response, explanation=explanation) from e
docker.errors.NotFound: 404 Client Error for http://docker-socket-proxy:2375/v1.45/containers/b54644c4c7220f5bd00693bde622cd43b3e089b566b54a0603a9c23a5df2caa0/start: Not Found ("network meltano_network not found")
[2025-02-04T20:19:48.243+0000] {local_task_job_runner.py:266} INFO - Task exited with return code 1
[2025-02-04T20:19:48.260+0000] {taskinstance.py:3895} INFO - 0 downstream tasks scheduled from follow-on schedule check
[2025-02-04T20:19:48.263+0000] {local_task_job_runner.py:245} INFO - ::endgroup::
