[2025-02-04T22:06:48.960+0000] {local_task_job_runner.py:123} INFO - ::group::Pre task execution logs
[2025-02-04T22:06:48.974+0000] {taskinstance.py:2613} INFO - Dependencies all met for dep_context=non-requeueable deps ti=<TaskInstance: northwind_meltano.extract_csv manual__2025-02-04T22:05:50.568509+00:00 [queued]>
[2025-02-04T22:06:48.981+0000] {taskinstance.py:2613} INFO - Dependencies all met for dep_context=requeueable deps ti=<TaskInstance: northwind_meltano.extract_csv manual__2025-02-04T22:05:50.568509+00:00 [queued]>
[2025-02-04T22:06:48.981+0000] {taskinstance.py:2866} INFO - Starting attempt 1 of 1
[2025-02-04T22:06:48.991+0000] {taskinstance.py:2889} INFO - Executing <Task(DockerOperator): extract_csv> on 2025-02-04 22:05:50.568509+00:00
[2025-02-04T22:06:48.998+0000] {standard_task_runner.py:104} INFO - Running: ['***', 'tasks', 'run', 'northwind_meltano', 'extract_csv', 'manual__2025-02-04T22:05:50.568509+00:00', '--job-id', '33', '--raw', '--subdir', 'DAGS_FOLDER/northwind_etl/northwind_meltano.py', '--cfg-path', '/tmp/tmpg1yfnqqs']
[2025-02-04T22:06:48.999+0000] {standard_task_runner.py:105} INFO - Job 33: Subtask extract_csv
[2025-02-04T22:06:49.001+0000] {logging_mixin.py:190} WARNING - /home/***/.local/lib/python3.12/site-packages/***/task/task_runner/standard_task_runner.py:70 DeprecationWarning: This process (pid=3856) is multi-threaded, use of fork() may lead to deadlocks in the child.
[2025-02-04T22:06:49.001+0000] {standard_task_runner.py:72} INFO - Started process 3857 to run task
[2025-02-04T22:06:49.031+0000] {task_command.py:467} INFO - Running <TaskInstance: northwind_meltano.extract_csv manual__2025-02-04T22:05:50.568509+00:00 [running]> on host 09d05643d017
[2025-02-04T22:06:49.100+0000] {taskinstance.py:3132} INFO - Exporting env vars: AIRFLOW_CTX_DAG_OWNER='gabriel' AIRFLOW_CTX_DAG_ID='northwind_meltano' AIRFLOW_CTX_TASK_ID='extract_csv' AIRFLOW_CTX_EXECUTION_DATE='2025-02-04T22:05:50.568509+00:00' AIRFLOW_CTX_TRY_NUMBER='1' AIRFLOW_CTX_DAG_RUN_ID='manual__2025-02-04T22:05:50.568509+00:00'
[2025-02-04T22:06:49.101+0000] {taskinstance.py:731} INFO - ::endgroup::
[2025-02-04T22:06:49.140+0000] {docker.py:379} INFO - Starting docker container from image meu-meltano
[2025-02-04T22:06:52.098+0000] {docker.py:73} INFO - Added extractor 'tap-csv' to your project
[2025-02-04T22:06:52.099+0000] {docker.py:73} INFO - Variant:	meltanolabs (default)
[2025-02-04T22:06:52.099+0000] {docker.py:73} INFO - Repository:	https://github.com/MeltanoLabs/tap-csv
[2025-02-04T22:06:52.099+0000] {docker.py:73} INFO - Documentation:	https://hub.meltano.com/extractors/tap-csv--meltanolabs
[2025-02-04T22:06:52.152+0000] {docker.py:73} INFO - [2m2025-02-04T22:06:52.151644Z[0m [[32m[1minfo     [0m] [1mInstalling extractor 'tap-csv'[0m
[2025-02-04T22:07:06.435+0000] {docker.py:73} INFO - [2m2025-02-04T22:07:06.434327Z[0m [[32m[1minfo     [0m] [1mInstalled extractor 'tap-csv' [0m
[2025-02-04T22:07:06.436+0000] {docker.py:73} INFO - 
[2025-02-04T22:07:06.436+0000] {docker.py:73} INFO - To learn more about extractor 'tap-csv', visit https://hub.meltano.com/extractors/tap-csv--meltanolabs
[2025-02-04T22:07:08.007+0000] {docker.py:73} INFO - [2m2025-02-04T22:07:08.005886Z[0m [[32m[1minfo     [0m] [1mThe default environment 'dev' will be ignored for `meltano config`. To configure a specific environment, please use the option `--environment=<environment name>`.[0m
[2025-02-04T22:07:08.057+0000] {docker.py:73} INFO - Need help fixing this problem? Visit http://melta.no/ for troubleshooting steps, or to
[2025-02-04T22:07:08.058+0000] {docker.py:73} INFO - join our friendly Slack community.
[2025-02-04T22:07:08.058+0000] {docker.py:73} INFO - 
[2025-02-04T22:07:08.059+0000] {docker.py:73} INFO - Failed to parse JSON array from string: '[/meltano/demo-project/input/csv/2024-01-02/order_details.csv]'
[2025-02-04T22:07:09.753+0000] {taskinstance.py:3311} ERROR - Task failed with exception
Traceback (most recent call last):
  File "/home/airflow/.local/lib/python3.12/site-packages/airflow/models/taskinstance.py", line 767, in _execute_task
    result = _execute_callable(context=context, **execute_callable_kwargs)
             ^^^^^^^^^^^^^^^^^^^^^^^^^^^^^^^^^^^^^^^^^^^^^^^^^^^^^^^^^^^^^
  File "/home/airflow/.local/lib/python3.12/site-packages/airflow/models/taskinstance.py", line 733, in _execute_callable
    return ExecutionCallableRunner(
           ^^^^^^^^^^^^^^^^^^^^^^^^
  File "/home/airflow/.local/lib/python3.12/site-packages/airflow/utils/operator_helpers.py", line 252, in run
    return self.func(*args, **kwargs)
           ^^^^^^^^^^^^^^^^^^^^^^^^^^
  File "/home/airflow/.local/lib/python3.12/site-packages/airflow/models/baseoperator.py", line 422, in wrapper
    return func(self, *args, **kwargs)
           ^^^^^^^^^^^^^^^^^^^^^^^^^^^
  File "/home/airflow/.local/lib/python3.12/site-packages/airflow/providers/docker/operators/docker.py", line 519, in execute
    return self._run_image()
           ^^^^^^^^^^^^^^^^^
  File "/home/airflow/.local/lib/python3.12/site-packages/airflow/providers/docker/operators/docker.py", line 396, in _run_image
    return self._run_image_with_mounts(self.mounts, add_tmp_variable=False)
           ^^^^^^^^^^^^^^^^^^^^^^^^^^^^^^^^^^^^^^^^^^^^^^^^^^^^^^^^^^^^^^^^
  File "/home/airflow/.local/lib/python3.12/site-packages/airflow/providers/docker/operators/docker.py", line 453, in _run_image_with_mounts
    raise DockerContainerFailedException(f"Docker container failed: {result!r}", logs=log_lines)
airflow.providers.docker.exceptions.DockerContainerFailedException: Docker container failed: {'StatusCode': 1}
[2025-02-04T22:07:09.759+0000] {taskinstance.py:1225} INFO - Marking task as FAILED. dag_id=northwind_meltano, task_id=extract_csv, run_id=manual__2025-02-04T22:05:50.568509+00:00, execution_date=20250204T220550, start_date=20250204T220648, end_date=20250204T220709
[2025-02-04T22:07:09.769+0000] {taskinstance.py:340} INFO - ::group::Post task execution logs
[2025-02-04T22:07:09.769+0000] {standard_task_runner.py:124} ERROR - Failed to execute job 33 for task extract_csv (Docker container failed: {'StatusCode': 1}; 3857)
Traceback (most recent call last):
  File "/home/airflow/.local/lib/python3.12/site-packages/airflow/task/task_runner/standard_task_runner.py", line 117, in _start_by_fork
    ret = args.func(args, dag=self.dag)
          ^^^^^^^^^^^^^^^^^^^^^^^^^^^^^
  File "/home/airflow/.local/lib/python3.12/site-packages/airflow/cli/cli_config.py", line 49, in command
    return func(*args, **kwargs)
           ^^^^^^^^^^^^^^^^^^^^^
  File "/home/airflow/.local/lib/python3.12/site-packages/airflow/utils/cli.py", line 116, in wrapper
    return f(*args, **kwargs)
           ^^^^^^^^^^^^^^^^^^
  File "/home/airflow/.local/lib/python3.12/site-packages/airflow/cli/commands/task_command.py", line 483, in task_run
    task_return_code = _run_task_by_selected_method(args, _dag, ti)
                       ^^^^^^^^^^^^^^^^^^^^^^^^^^^^^^^^^^^^^^^^^^^^
  File "/home/airflow/.local/lib/python3.12/site-packages/airflow/cli/commands/task_command.py", line 256, in _run_task_by_selected_method
    return _run_raw_task(args, ti)
           ^^^^^^^^^^^^^^^^^^^^^^^
  File "/home/airflow/.local/lib/python3.12/site-packages/airflow/cli/commands/task_command.py", line 341, in _run_raw_task
    return ti._run_raw_task(
           ^^^^^^^^^^^^^^^^^
  File "/home/airflow/.local/lib/python3.12/site-packages/airflow/utils/session.py", line 97, in wrapper
    return func(*args, session=session, **kwargs)
           ^^^^^^^^^^^^^^^^^^^^^^^^^^^^^^^^^^^^^^
  File "/home/airflow/.local/lib/python3.12/site-packages/airflow/models/taskinstance.py", line 3005, in _run_raw_task
    return _run_raw_task(
           ^^^^^^^^^^^^^^
  File "/home/airflow/.local/lib/python3.12/site-packages/airflow/models/taskinstance.py", line 273, in _run_raw_task
    TaskInstance._execute_task_with_callbacks(
  File "/home/airflow/.local/lib/python3.12/site-packages/airflow/models/taskinstance.py", line 3159, in _execute_task_with_callbacks
    result = self._execute_task(context, task_orig)
             ^^^^^^^^^^^^^^^^^^^^^^^^^^^^^^^^^^^^^^
  File "/home/airflow/.local/lib/python3.12/site-packages/airflow/models/taskinstance.py", line 3183, in _execute_task
    return _execute_task(self, context, task_orig)
           ^^^^^^^^^^^^^^^^^^^^^^^^^^^^^^^^^^^^^^^
  File "/home/airflow/.local/lib/python3.12/site-packages/airflow/models/taskinstance.py", line 767, in _execute_task
    result = _execute_callable(context=context, **execute_callable_kwargs)
             ^^^^^^^^^^^^^^^^^^^^^^^^^^^^^^^^^^^^^^^^^^^^^^^^^^^^^^^^^^^^^
  File "/home/airflow/.local/lib/python3.12/site-packages/airflow/models/taskinstance.py", line 733, in _execute_callable
    return ExecutionCallableRunner(
           ^^^^^^^^^^^^^^^^^^^^^^^^
  File "/home/airflow/.local/lib/python3.12/site-packages/airflow/utils/operator_helpers.py", line 252, in run
    return self.func(*args, **kwargs)
           ^^^^^^^^^^^^^^^^^^^^^^^^^^
  File "/home/airflow/.local/lib/python3.12/site-packages/airflow/models/baseoperator.py", line 422, in wrapper
    return func(self, *args, **kwargs)
           ^^^^^^^^^^^^^^^^^^^^^^^^^^^
  File "/home/airflow/.local/lib/python3.12/site-packages/airflow/providers/docker/operators/docker.py", line 519, in execute
    return self._run_image()
           ^^^^^^^^^^^^^^^^^
  File "/home/airflow/.local/lib/python3.12/site-packages/airflow/providers/docker/operators/docker.py", line 396, in _run_image
    return self._run_image_with_mounts(self.mounts, add_tmp_variable=False)
           ^^^^^^^^^^^^^^^^^^^^^^^^^^^^^^^^^^^^^^^^^^^^^^^^^^^^^^^^^^^^^^^^
  File "/home/airflow/.local/lib/python3.12/site-packages/airflow/providers/docker/operators/docker.py", line 453, in _run_image_with_mounts
    raise DockerContainerFailedException(f"Docker container failed: {result!r}", logs=log_lines)
airflow.providers.docker.exceptions.DockerContainerFailedException: Docker container failed: {'StatusCode': 1}
[2025-02-04T22:07:09.790+0000] {local_task_job_runner.py:266} INFO - Task exited with return code 1
[2025-02-04T22:07:09.807+0000] {taskinstance.py:3895} INFO - 0 downstream tasks scheduled from follow-on schedule check
[2025-02-04T22:07:09.809+0000] {local_task_job_runner.py:245} INFO - ::endgroup::
