[2025-02-04T21:18:42.996+0000] {local_task_job_runner.py:123} INFO - ::group::Pre task execution logs
[2025-02-04T21:18:43.009+0000] {taskinstance.py:2613} INFO - Dependencies all met for dep_context=non-requeueable deps ti=<TaskInstance: northwind_meltano.setup_meltano manual__2025-02-04T21:18:41.882566+00:00 [queued]>
[2025-02-04T21:18:43.015+0000] {taskinstance.py:2613} INFO - Dependencies all met for dep_context=requeueable deps ti=<TaskInstance: northwind_meltano.setup_meltano manual__2025-02-04T21:18:41.882566+00:00 [queued]>
[2025-02-04T21:18:43.016+0000] {taskinstance.py:2866} INFO - Starting attempt 1 of 1
[2025-02-04T21:18:43.026+0000] {taskinstance.py:2889} INFO - Executing <Task(DockerOperator): setup_meltano> on 2025-02-04 21:18:41.882566+00:00
[2025-02-04T21:18:43.032+0000] {standard_task_runner.py:104} INFO - Running: ['***', 'tasks', 'run', 'northwind_meltano', 'setup_meltano', 'manual__2025-02-04T21:18:41.882566+00:00', '--job-id', '26', '--raw', '--subdir', 'DAGS_FOLDER/northwind_etl/northwind_meltano.py', '--cfg-path', '/tmp/tmpj311m9ls']
[2025-02-04T21:18:43.033+0000] {standard_task_runner.py:105} INFO - Job 26: Subtask setup_meltano
[2025-02-04T21:18:43.034+0000] {logging_mixin.py:190} WARNING - /home/***/.local/lib/python3.12/site-packages/***/task/task_runner/standard_task_runner.py:70 DeprecationWarning: This process (pid=2178) is multi-threaded, use of fork() may lead to deadlocks in the child.
[2025-02-04T21:18:43.035+0000] {standard_task_runner.py:72} INFO - Started process 2179 to run task
[2025-02-04T21:18:43.065+0000] {task_command.py:467} INFO - Running <TaskInstance: northwind_meltano.setup_meltano manual__2025-02-04T21:18:41.882566+00:00 [running]> on host 09d05643d017
[2025-02-04T21:18:43.129+0000] {taskinstance.py:3132} INFO - Exporting env vars: AIRFLOW_CTX_DAG_OWNER='gabriel' AIRFLOW_CTX_DAG_ID='northwind_meltano' AIRFLOW_CTX_TASK_ID='setup_meltano' AIRFLOW_CTX_EXECUTION_DATE='2025-02-04T21:18:41.882566+00:00' AIRFLOW_CTX_TRY_NUMBER='1' AIRFLOW_CTX_DAG_RUN_ID='manual__2025-02-04T21:18:41.882566+00:00'
[2025-02-04T21:18:43.130+0000] {taskinstance.py:731} INFO - ::endgroup::
[2025-02-04T21:18:43.185+0000] {docker.py:379} INFO - Starting docker container from image meu-meltano
[2025-02-04T21:18:43.194+0000] {docker.py:387} WARNING - Using remote engine or docker-in-docker and mounting temporary volume from host is not supported. Falling back to `mount_tmp_dir=False` mode. You can set `mount_tmp_dir` parameter to False to disable mounting and remove the warning
[2025-02-04T21:18:47.356+0000] {docker.py:73} INFO - Creating .meltano folder
[2025-02-04T21:18:47.358+0000] {docker.py:73} INFO - created .meltano in /meltano/demo-project/.meltano
[2025-02-04T21:18:47.359+0000] {docker.py:73} INFO - Creating project files...
[2025-02-04T21:18:47.393+0000] {docker.py:73} INFO -    |-- meltano.yml
[2025-02-04T21:18:47.394+0000] {docker.py:73} INFO -    |-- README.md
[2025-02-04T21:18:47.394+0000] {docker.py:73} INFO -    |-- requirements.txt
[2025-02-04T21:18:47.394+0000] {docker.py:73} INFO -    |-- output/.gitignore
[2025-02-04T21:18:47.395+0000] {docker.py:73} INFO -    |-- .gitignore
[2025-02-04T21:18:47.395+0000] {docker.py:73} INFO -    |-- extract/.gitkeep
[2025-02-04T21:18:47.395+0000] {docker.py:73} INFO -    |-- load/.gitkeep
[2025-02-04T21:18:47.396+0000] {docker.py:73} INFO -    |-- transform/.gitkeep
[2025-02-04T21:18:47.396+0000] {docker.py:73} INFO -    |-- analyze/.gitkeep
[2025-02-04T21:18:47.396+0000] {docker.py:73} INFO -    |-- notebook/.gitkeep
[2025-02-04T21:18:47.396+0000] {docker.py:73} INFO -    |-- orchestrate/.gitkeep
[2025-02-04T21:18:47.637+0000] {docker.py:73} INFO - Creating system database...
[2025-02-04T21:18:47.966+0000] {docker.py:73} INFO -   Done!
[2025-02-04T21:18:47.967+0000] {docker.py:73} INFO - 
[2025-02-04T21:18:47.967+0000] {docker.py:73} INFO - 
[2025-02-04T21:18:47.968+0000] {docker.py:73} INFO - 
[2025-02-04T21:18:47.968+0000] {docker.py:73} INFO -                           â–ˆâ–ˆâ–ˆâ–ˆ   â–ˆâ–ˆâ–ˆâ–ˆâ–ˆ
[2025-02-04T21:18:47.968+0000] {docker.py:73} INFO -                          â–‘â–‘â–ˆâ–ˆâ–ˆ  â–‘â–‘â–ˆâ–ˆâ–ˆ
[2025-02-04T21:18:47.969+0000] {docker.py:73} INFO -  â–ˆâ–ˆâ–ˆâ–ˆâ–ˆâ–ˆâ–ˆâ–ˆâ–ˆâ–ˆâ–ˆâ–ˆâ–ˆ    â–ˆâ–ˆâ–ˆâ–ˆâ–ˆâ–ˆ  â–‘â–ˆâ–ˆâ–ˆ  â–ˆâ–ˆâ–ˆâ–ˆâ–ˆâ–ˆâ–ˆ    â–ˆâ–ˆâ–ˆâ–ˆâ–ˆâ–ˆ   â–ˆâ–ˆâ–ˆâ–ˆâ–ˆâ–ˆâ–ˆâ–ˆ    â–ˆâ–ˆâ–ˆâ–ˆâ–ˆâ–ˆ
[2025-02-04T21:18:47.969+0000] {docker.py:73} INFO - â–‘â–‘â–ˆâ–ˆâ–ˆâ–‘â–‘â–ˆâ–ˆâ–ˆâ–‘â–‘â–ˆâ–ˆâ–ˆ  â–ˆâ–ˆâ–ˆâ–‘â–‘â–ˆâ–ˆâ–ˆ â–‘â–ˆâ–ˆâ–ˆ â–‘â–‘â–‘â–ˆâ–ˆâ–ˆâ–‘    â–‘â–‘â–‘â–‘â–‘â–ˆâ–ˆâ–ˆ â–‘â–‘â–ˆâ–ˆâ–ˆâ–‘â–‘â–ˆâ–ˆâ–ˆ  â–ˆâ–ˆâ–ˆâ–‘â–‘â–ˆâ–ˆâ–ˆ
[2025-02-04T21:18:47.970+0000] {docker.py:73} INFO -  â–‘â–ˆâ–ˆâ–ˆ â–‘â–ˆâ–ˆâ–ˆ â–‘â–ˆâ–ˆâ–ˆ â–‘â–ˆâ–ˆâ–ˆâ–ˆâ–ˆâ–ˆâ–ˆ  â–‘â–ˆâ–ˆâ–ˆ   â–‘â–ˆâ–ˆâ–ˆ      â–ˆâ–ˆâ–ˆâ–ˆâ–ˆâ–ˆâ–ˆ  â–‘â–ˆâ–ˆâ–ˆ â–‘â–ˆâ–ˆâ–ˆ â–‘â–ˆâ–ˆâ–ˆ â–‘â–ˆâ–ˆâ–ˆ
[2025-02-04T21:18:47.970+0000] {docker.py:73} INFO -  â–‘â–ˆâ–ˆâ–ˆ â–‘â–ˆâ–ˆâ–ˆ â–‘â–ˆâ–ˆâ–ˆ â–‘â–ˆâ–ˆâ–ˆâ–‘â–‘â–‘   â–‘â–ˆâ–ˆâ–ˆ   â–‘â–ˆâ–ˆâ–ˆ â–ˆâ–ˆâ–ˆ â–ˆâ–ˆâ–ˆâ–‘â–‘â–ˆâ–ˆâ–ˆ  â–‘â–ˆâ–ˆâ–ˆ â–‘â–ˆâ–ˆâ–ˆ â–‘â–ˆâ–ˆâ–ˆ â–‘â–ˆâ–ˆâ–ˆ
[2025-02-04T21:18:47.970+0000] {docker.py:73} INFO -  â–ˆâ–ˆâ–ˆâ–ˆâ–ˆâ–‘â–ˆâ–ˆâ–ˆ â–ˆâ–ˆâ–ˆâ–ˆâ–ˆâ–‘â–‘â–ˆâ–ˆâ–ˆâ–ˆâ–ˆâ–ˆ  â–ˆâ–ˆâ–ˆâ–ˆâ–ˆ  â–‘â–‘â–ˆâ–ˆâ–ˆâ–ˆâ–ˆ â–‘â–‘â–ˆâ–ˆâ–ˆâ–ˆâ–ˆâ–ˆâ–ˆâ–ˆ â–ˆâ–ˆâ–ˆâ–ˆ â–ˆâ–ˆâ–ˆâ–ˆâ–ˆâ–‘â–‘â–ˆâ–ˆâ–ˆâ–ˆâ–ˆâ–ˆ
[2025-02-04T21:18:47.971+0000] {docker.py:73} INFO - â–‘â–‘â–‘â–‘â–‘ â–‘â–‘â–‘ â–‘â–‘â–‘â–‘â–‘  â–‘â–‘â–‘â–‘â–‘â–‘  â–‘â–‘â–‘â–‘â–‘    â–‘â–‘â–‘â–‘â–‘   â–‘â–‘â–‘â–‘â–‘â–‘â–‘â–‘ â–‘â–‘â–‘â–‘ â–‘â–‘â–‘â–‘â–‘  â–‘â–‘â–‘â–‘â–‘â–‘
[2025-02-04T21:18:47.971+0000] {docker.py:73} INFO - 
[2025-02-04T21:18:47.972+0000] {docker.py:73} INFO - 
[2025-02-04T21:18:47.972+0000] {docker.py:73} INFO - 
[2025-02-04T21:18:47.972+0000] {docker.py:73} INFO - Your project has been created!
[2025-02-04T21:18:47.973+0000] {docker.py:73} INFO - 
[2025-02-04T21:18:47.973+0000] {docker.py:73} INFO - Meltano Environments initialized with dev, staging, and prod.
[2025-02-04T21:18:47.974+0000] {docker.py:73} INFO - To learn more about Environments visit: https://docs.meltano.com/concepts/environments
[2025-02-04T21:18:47.974+0000] {docker.py:73} INFO - 
[2025-02-04T21:18:47.975+0000] {docker.py:73} INFO - Next steps:
[2025-02-04T21:18:47.975+0000] {docker.py:73} INFO -   Visit https://docs.meltano.com/getting-started/part1 to learn where to go from here
[2025-02-04T21:18:51.397+0000] {docker.py:73} INFO - Added extractor 'tap-postgres' to your project
[2025-02-04T21:18:51.398+0000] {docker.py:73} INFO - Variant:	meltanolabs (default)
[2025-02-04T21:18:51.398+0000] {docker.py:73} INFO - Repository:	https://github.com/MeltanoLabs/tap-postgres
[2025-02-04T21:18:51.399+0000] {docker.py:73} INFO - Documentation:	https://hub.meltano.com/extractors/tap-postgres--meltanolabs
[2025-02-04T21:18:51.572+0000] {docker.py:73} INFO - [2m2025-02-04T21:18:51.571262Z[0m [[32m[1minfo     [0m] [1mInstalling extractor 'tap-postgres'[0m
[2025-02-04T21:24:15.251+0000] {docker.py:73} INFO - [2m2025-02-04T21:24:15.250158Z[0m [[32m[1minfo     [0m] [1mInstalled extractor 'tap-postgres'[0m
[2025-02-04T21:24:15.252+0000] {docker.py:73} INFO - 
[2025-02-04T21:24:15.252+0000] {docker.py:73} INFO - To learn more about extractor 'tap-postgres', visit https://hub.meltano.com/extractors/tap-postgres--meltanolabs
[2025-02-04T21:24:16.953+0000] {docker.py:73} INFO - [2m2025-02-04T21:24:16.952031Z[0m [[32m[1minfo     [0m] [1mEnvironment 'dev' is active   [0m
[2025-02-04T21:24:17.247+0000] {docker.py:73} INFO - Extractor 'tap-postgres' setting 'host' was set in the active environment in `meltano.yml`: 'northwind_db'
[2025-02-04T21:24:18.961+0000] {docker.py:73} INFO - [2m2025-02-04T21:24:18.959802Z[0m [[32m[1minfo     [0m] [1mEnvironment 'dev' is active   [0m
[2025-02-04T21:24:19.248+0000] {docker.py:73} INFO - Extractor 'tap-postgres' setting 'port' was set in the active environment in `meltano.yml`: 5432
[2025-02-04T21:24:20.953+0000] {docker.py:73} INFO - [2m2025-02-04T21:24:20.952490Z[0m [[32m[1minfo     [0m] [1mEnvironment 'dev' is active   [0m
[2025-02-04T21:24:21.238+0000] {docker.py:73} INFO - Extractor 'tap-postgres' setting 'user' was set in the active environment in `meltano.yml`: 'northwind_user'
[2025-02-04T21:24:22.947+0000] {docker.py:73} INFO - [2m2025-02-04T21:24:22.946532Z[0m [[32m[1minfo     [0m] [1mEnvironment 'dev' is active   [0m
[2025-02-04T21:24:23.163+0000] {docker.py:73} INFO - Extractor 'tap-postgres' setting 'password' was set in `.env`: (redacted)
[2025-02-04T21:24:24.878+0000] {docker.py:73} INFO - [2m2025-02-04T21:24:24.877332Z[0m [[32m[1minfo     [0m] [1mEnvironment 'dev' is active   [0m
[2025-02-04T21:24:25.193+0000] {docker.py:73} INFO - Extractor 'tap-postgres' setting 'database' was set in the active environment in `meltano.yml`: 'northwind'
[2025-02-04T21:24:26.886+0000] {docker.py:73} INFO - [2m2025-02-04T21:24:26.884741Z[0m [[32m[1minfo     [0m] [1mEnvironment 'dev' is active   [0m
[2025-02-04T21:24:27.178+0000] {docker.py:73} INFO - Extractor 'tap-postgres' setting 'filter_schemas' was set in the active environment in `meltano.yml`: ['public']
[2025-02-04T21:24:28.912+0000] {docker.py:73} INFO - [2m2025-02-04T21:24:28.910961Z[0m [[32m[1minfo     [0m] [1mThe default environment 'dev' will be ignored for `meltano config`. To configure a specific environment, please use the option `--environment=<environment name>`.[0m
[2025-02-04T21:24:29.065+0000] {docker.py:73} INFO - Usage: meltano config PLUGIN_NAME list [OPTIONS]
[2025-02-04T21:24:29.066+0000] {docker.py:73} INFO - Try 'meltano config PLUGIN_NAME list --help' for help.
[2025-02-04T21:24:29.066+0000] {docker.py:73} INFO - 
[2025-02-04T21:24:29.067+0000] {docker.py:73} INFO - Error: No such option: --format
[2025-02-04T21:24:30.188+0000] {taskinstance.py:3311} ERROR - Task failed with exception
Traceback (most recent call last):
  File "/home/airflow/.local/lib/python3.12/site-packages/docker/api/client.py", line 275, in _raise_for_status
    response.raise_for_status()
  File "/home/airflow/.local/lib/python3.12/site-packages/requests/models.py", line 1024, in raise_for_status
    raise HTTPError(http_error_msg, response=self)
requests.exceptions.HTTPError: 400 Client Error: Bad Request for url: http://docker-socket-proxy:2375/v1.45/containers/create

The above exception was the direct cause of the following exception:

Traceback (most recent call last):
  File "/home/airflow/.local/lib/python3.12/site-packages/airflow/providers/docker/operators/docker.py", line 384, in _run_image
    return self._run_image_with_mounts([*self.mounts, tmp_mount], add_tmp_variable=True)
           ^^^^^^^^^^^^^^^^^^^^^^^^^^^^^^^^^^^^^^^^^^^^^^^^^^^^^^^^^^^^^^^^^^^^^^^^^^^^^
  File "/home/airflow/.local/lib/python3.12/site-packages/airflow/providers/docker/operators/docker.py", line 411, in _run_image_with_mounts
    self.container = self.cli.create_container(
                     ^^^^^^^^^^^^^^^^^^^^^^^^^^
  File "/home/airflow/.local/lib/python3.12/site-packages/docker/api/container.py", line 440, in create_container
    return self.create_container_from_config(config, name, platform)
           ^^^^^^^^^^^^^^^^^^^^^^^^^^^^^^^^^^^^^^^^^^^^^^^^^^^^^^^^^
  File "/home/airflow/.local/lib/python3.12/site-packages/docker/api/container.py", line 457, in create_container_from_config
    return self._result(res, True)
           ^^^^^^^^^^^^^^^^^^^^^^^
  File "/home/airflow/.local/lib/python3.12/site-packages/docker/api/client.py", line 281, in _result
    self._raise_for_status(response)
  File "/home/airflow/.local/lib/python3.12/site-packages/docker/api/client.py", line 277, in _raise_for_status
    raise create_api_error_from_http_exception(e) from e
          ^^^^^^^^^^^^^^^^^^^^^^^^^^^^^^^^^^^^^^^
  File "/home/airflow/.local/lib/python3.12/site-packages/docker/errors.py", line 39, in create_api_error_from_http_exception
    raise cls(e, response=response, explanation=explanation) from e
docker.errors.APIError: 400 Client Error for http://docker-socket-proxy:2375/v1.45/containers/create: Bad Request ("invalid mount config for type "bind": bind source path does not exist: /tmp/airflowtmpfb2bxh_y")

During handling of the above exception, another exception occurred:

Traceback (most recent call last):
  File "/home/airflow/.local/lib/python3.12/site-packages/airflow/models/taskinstance.py", line 767, in _execute_task
    result = _execute_callable(context=context, **execute_callable_kwargs)
             ^^^^^^^^^^^^^^^^^^^^^^^^^^^^^^^^^^^^^^^^^^^^^^^^^^^^^^^^^^^^^
  File "/home/airflow/.local/lib/python3.12/site-packages/airflow/models/taskinstance.py", line 733, in _execute_callable
    return ExecutionCallableRunner(
           ^^^^^^^^^^^^^^^^^^^^^^^^
  File "/home/airflow/.local/lib/python3.12/site-packages/airflow/utils/operator_helpers.py", line 252, in run
    return self.func(*args, **kwargs)
           ^^^^^^^^^^^^^^^^^^^^^^^^^^
  File "/home/airflow/.local/lib/python3.12/site-packages/airflow/models/baseoperator.py", line 422, in wrapper
    return func(self, *args, **kwargs)
           ^^^^^^^^^^^^^^^^^^^^^^^^^^^
  File "/home/airflow/.local/lib/python3.12/site-packages/airflow/providers/docker/operators/docker.py", line 519, in execute
    return self._run_image()
           ^^^^^^^^^^^^^^^^^
  File "/home/airflow/.local/lib/python3.12/site-packages/airflow/providers/docker/operators/docker.py", line 393, in _run_image
    return self._run_image_with_mounts(self.mounts, add_tmp_variable=False)
           ^^^^^^^^^^^^^^^^^^^^^^^^^^^^^^^^^^^^^^^^^^^^^^^^^^^^^^^^^^^^^^^^
  File "/home/airflow/.local/lib/python3.12/site-packages/airflow/providers/docker/operators/docker.py", line 453, in _run_image_with_mounts
    raise DockerContainerFailedException(f"Docker container failed: {result!r}", logs=log_lines)
airflow.providers.docker.exceptions.DockerContainerFailedException: Docker container failed: {'StatusCode': 2}
[2025-02-04T21:24:30.198+0000] {taskinstance.py:1225} INFO - Marking task as FAILED. dag_id=northwind_meltano, task_id=setup_meltano, run_id=manual__2025-02-04T21:18:41.882566+00:00, execution_date=20250204T211841, start_date=20250204T211843, end_date=20250204T212430
[2025-02-04T21:24:30.211+0000] {taskinstance.py:340} INFO - ::group::Post task execution logs
[2025-02-04T21:24:30.211+0000] {standard_task_runner.py:124} ERROR - Failed to execute job 26 for task setup_meltano (Docker container failed: {'StatusCode': 2}; 2179)
Traceback (most recent call last):
  File "/home/airflow/.local/lib/python3.12/site-packages/docker/api/client.py", line 275, in _raise_for_status
    response.raise_for_status()
  File "/home/airflow/.local/lib/python3.12/site-packages/requests/models.py", line 1024, in raise_for_status
    raise HTTPError(http_error_msg, response=self)
requests.exceptions.HTTPError: 400 Client Error: Bad Request for url: http://docker-socket-proxy:2375/v1.45/containers/create

The above exception was the direct cause of the following exception:

Traceback (most recent call last):
  File "/home/airflow/.local/lib/python3.12/site-packages/airflow/providers/docker/operators/docker.py", line 384, in _run_image
    return self._run_image_with_mounts([*self.mounts, tmp_mount], add_tmp_variable=True)
           ^^^^^^^^^^^^^^^^^^^^^^^^^^^^^^^^^^^^^^^^^^^^^^^^^^^^^^^^^^^^^^^^^^^^^^^^^^^^^
  File "/home/airflow/.local/lib/python3.12/site-packages/airflow/providers/docker/operators/docker.py", line 411, in _run_image_with_mounts
    self.container = self.cli.create_container(
                     ^^^^^^^^^^^^^^^^^^^^^^^^^^
  File "/home/airflow/.local/lib/python3.12/site-packages/docker/api/container.py", line 440, in create_container
    return self.create_container_from_config(config, name, platform)
           ^^^^^^^^^^^^^^^^^^^^^^^^^^^^^^^^^^^^^^^^^^^^^^^^^^^^^^^^^
  File "/home/airflow/.local/lib/python3.12/site-packages/docker/api/container.py", line 457, in create_container_from_config
    return self._result(res, True)
           ^^^^^^^^^^^^^^^^^^^^^^^
  File "/home/airflow/.local/lib/python3.12/site-packages/docker/api/client.py", line 281, in _result
    self._raise_for_status(response)
  File "/home/airflow/.local/lib/python3.12/site-packages/docker/api/client.py", line 277, in _raise_for_status
    raise create_api_error_from_http_exception(e) from e
          ^^^^^^^^^^^^^^^^^^^^^^^^^^^^^^^^^^^^^^^
  File "/home/airflow/.local/lib/python3.12/site-packages/docker/errors.py", line 39, in create_api_error_from_http_exception
    raise cls(e, response=response, explanation=explanation) from e
docker.errors.APIError: 400 Client Error for http://docker-socket-proxy:2375/v1.45/containers/create: Bad Request ("invalid mount config for type "bind": bind source path does not exist: /tmp/airflowtmpfb2bxh_y")

During handling of the above exception, another exception occurred:

Traceback (most recent call last):
  File "/home/airflow/.local/lib/python3.12/site-packages/airflow/task/task_runner/standard_task_runner.py", line 117, in _start_by_fork
    ret = args.func(args, dag=self.dag)
          ^^^^^^^^^^^^^^^^^^^^^^^^^^^^^
  File "/home/airflow/.local/lib/python3.12/site-packages/airflow/cli/cli_config.py", line 49, in command
    return func(*args, **kwargs)
           ^^^^^^^^^^^^^^^^^^^^^
  File "/home/airflow/.local/lib/python3.12/site-packages/airflow/utils/cli.py", line 116, in wrapper
    return f(*args, **kwargs)
           ^^^^^^^^^^^^^^^^^^
  File "/home/airflow/.local/lib/python3.12/site-packages/airflow/cli/commands/task_command.py", line 483, in task_run
    task_return_code = _run_task_by_selected_method(args, _dag, ti)
                       ^^^^^^^^^^^^^^^^^^^^^^^^^^^^^^^^^^^^^^^^^^^^
  File "/home/airflow/.local/lib/python3.12/site-packages/airflow/cli/commands/task_command.py", line 256, in _run_task_by_selected_method
    return _run_raw_task(args, ti)
           ^^^^^^^^^^^^^^^^^^^^^^^
  File "/home/airflow/.local/lib/python3.12/site-packages/airflow/cli/commands/task_command.py", line 341, in _run_raw_task
    return ti._run_raw_task(
           ^^^^^^^^^^^^^^^^^
  File "/home/airflow/.local/lib/python3.12/site-packages/airflow/utils/session.py", line 97, in wrapper
    return func(*args, session=session, **kwargs)
           ^^^^^^^^^^^^^^^^^^^^^^^^^^^^^^^^^^^^^^
  File "/home/airflow/.local/lib/python3.12/site-packages/airflow/models/taskinstance.py", line 3005, in _run_raw_task
    return _run_raw_task(
           ^^^^^^^^^^^^^^
  File "/home/airflow/.local/lib/python3.12/site-packages/airflow/models/taskinstance.py", line 273, in _run_raw_task
    TaskInstance._execute_task_with_callbacks(
  File "/home/airflow/.local/lib/python3.12/site-packages/airflow/models/taskinstance.py", line 3159, in _execute_task_with_callbacks
    result = self._execute_task(context, task_orig)
             ^^^^^^^^^^^^^^^^^^^^^^^^^^^^^^^^^^^^^^
  File "/home/airflow/.local/lib/python3.12/site-packages/airflow/models/taskinstance.py", line 3183, in _execute_task
    return _execute_task(self, context, task_orig)
           ^^^^^^^^^^^^^^^^^^^^^^^^^^^^^^^^^^^^^^^
  File "/home/airflow/.local/lib/python3.12/site-packages/airflow/models/taskinstance.py", line 767, in _execute_task
    result = _execute_callable(context=context, **execute_callable_kwargs)
             ^^^^^^^^^^^^^^^^^^^^^^^^^^^^^^^^^^^^^^^^^^^^^^^^^^^^^^^^^^^^^
  File "/home/airflow/.local/lib/python3.12/site-packages/airflow/models/taskinstance.py", line 733, in _execute_callable
    return ExecutionCallableRunner(
           ^^^^^^^^^^^^^^^^^^^^^^^^
  File "/home/airflow/.local/lib/python3.12/site-packages/airflow/utils/operator_helpers.py", line 252, in run
    return self.func(*args, **kwargs)
           ^^^^^^^^^^^^^^^^^^^^^^^^^^
  File "/home/airflow/.local/lib/python3.12/site-packages/airflow/models/baseoperator.py", line 422, in wrapper
    return func(self, *args, **kwargs)
           ^^^^^^^^^^^^^^^^^^^^^^^^^^^
  File "/home/airflow/.local/lib/python3.12/site-packages/airflow/providers/docker/operators/docker.py", line 519, in execute
    return self._run_image()
           ^^^^^^^^^^^^^^^^^
  File "/home/airflow/.local/lib/python3.12/site-packages/airflow/providers/docker/operators/docker.py", line 393, in _run_image
    return self._run_image_with_mounts(self.mounts, add_tmp_variable=False)
           ^^^^^^^^^^^^^^^^^^^^^^^^^^^^^^^^^^^^^^^^^^^^^^^^^^^^^^^^^^^^^^^^
  File "/home/airflow/.local/lib/python3.12/site-packages/airflow/providers/docker/operators/docker.py", line 453, in _run_image_with_mounts
    raise DockerContainerFailedException(f"Docker container failed: {result!r}", logs=log_lines)
airflow.providers.docker.exceptions.DockerContainerFailedException: Docker container failed: {'StatusCode': 2}
[2025-02-04T21:24:30.232+0000] {local_task_job_runner.py:266} INFO - Task exited with return code 1
[2025-02-04T21:24:30.244+0000] {taskinstance.py:3895} INFO - 0 downstream tasks scheduled from follow-on schedule check
[2025-02-04T21:24:30.246+0000] {local_task_job_runner.py:245} INFO - ::endgroup::
